<?xml version="1.0" ?>
<robot name="MOBERT-M5_002_A02_keep" xmlns:xacro="http://www.ros.org/wiki/xacro">

<xacro:include filename="$(find MOBERT-M5_002_A02_keep_description)/urdf/materials.xacro" />
<xacro:include filename="$(find MOBERT-M5_002_A02_keep_description)/urdf/MOBERT-M5_002_A02_keep.ros2control" />
<xacro:include filename="$(find MOBERT-M5_002_A02_keep_description)/urdf/MOBERT-M5_002_A02_keep.gazebo" />
<link name="base_link">
  <inertial>
    <origin xyz="-0.00022540692386026869 0.40916055898724113 0.0010912243325675167" rpy="0 0 0"/>
    <mass value="94.2120983245277"/>
    <inertia ixx="11.906526" iyy="6.372426" izz="10.42893" ixy="0.000998" iyz="0.120009" ixz="-0.004008"/>
  </inertial>
  <visual>
    <origin xyz="0 0 0" rpy="0 0 0"/>
    <geometry>
      <mesh filename="file://$(find MOBERT-M5_002_A02_keep_description)/meshes/base_link.stl" scale="0.001 0.001 0.001"/>
    </geometry>
    <material name="silver"/>
  </visual>
  <collision>
    <origin xyz="0 0 0" rpy="0 0 0"/>
    <geometry>
      <mesh filename="file://$(find MOBERT-M5_002_A02_keep_description)/meshes/base_link.stl" scale="0.001 0.001 0.001"/>
    </geometry>
  </collision>
</link>

<link name="lidar_1_1">
  <inertial>
    <origin xyz="8.545634555286158e-07 -0.0321875031777136 -0.0007209133160184789" rpy="0 0 0"/>
    <mass value="3.0353242430635783"/>
    <inertia ixx="0.002757" iyy="0.003051" izz="0.002716" ixy="-0.0" iyz="6.4e-05" ixz="0.0"/>
  </inertial>
  <visual>
    <origin xyz="9.7e-05 -0.181095 -0.266597" rpy="0 0 0"/>
    <geometry>
      <mesh filename="file://$(find MOBERT-M5_002_A02_keep_description)/meshes/lidar_1_1.stl" scale="0.001 0.001 0.001"/>
    </geometry>
    <material name="silver"/>
  </visual>
  <collision>
    <origin xyz="9.7e-05 -0.181095 -0.266597" rpy="0 0 0"/>
    <geometry>
      <mesh filename="file://$(find MOBERT-M5_002_A02_keep_description)/meshes/lidar_1_1.stl" scale="0.001 0.001 0.001"/>
    </geometry>
  </collision>
</link>

<link name="left_wheel_1_1">
  <inertial>
    <origin xyz="-0.024000000004620048 -5.032641506849678e-06 -7.999999954654523e-08" rpy="0 0 0"/>
    <mass value="11.102788603583125"/>
    <inertia ixx="0.052065" iyy="0.028163" izz="0.028166" ixy="-0.0" iyz="-0.0" ixz="-0.0"/>
  </inertial>
  <visual>
    <origin xyz="-0.2205 -0.096843 -0.000881" rpy="0 0 0"/>
    <geometry>
      <mesh filename="file://$(find MOBERT-M5_002_A02_keep_description)/meshes/left_wheel_1_1.stl" scale="0.001 0.001 0.001"/>
    </geometry>
    <material name="silver"/>
  </visual>
  <collision>
    <origin xyz="-0.2205 -0.096843 -0.000881" rpy="0 0 0"/>
    <geometry>
      <mesh filename="file://$(find MOBERT-M5_002_A02_keep_description)/meshes/left_wheel_1_1.stl" scale="0.001 0.001 0.001"/>
    </geometry>
  </collision>
</link>

<link name="right_wheel_1_1">
  <inertial>
    <origin xyz="0.023999999995379023 -5.032641506849678e-06 -7.999999954654523e-08" rpy="0 0 0"/>
    <mass value="11.102788603583125"/>
    <inertia ixx="0.052065" iyy="0.028163" izz="0.028166" ixy="-0.0" iyz="-0.0" ixz="-0.0"/>
  </inertial>
  <visual>
    <origin xyz="0.2205 -0.096843 -0.000881" rpy="0 0 0"/>
    <geometry>
      <mesh filename="file://$(find MOBERT-M5_002_A02_keep_description)/meshes/right_wheel_1_1.stl" scale="0.001 0.001 0.001"/>
    </geometry>
    <material name="silver"/>
  </visual>
  <collision>
    <origin xyz="0.2205 -0.096843 -0.000881" rpy="0 0 0"/>
    <geometry>
      <mesh filename="file://$(find MOBERT-M5_002_A02_keep_description)/meshes/right_wheel_1_1.stl" scale="0.001 0.001 0.001"/>
    </geometry>
  </collision>
</link>

<joint name="Rigid 1" type="fixed">
  <origin xyz="-9.7e-05 0.181095 0.266597" rpy="0 0 0"/>
  <parent link="base_link"/>
  <child link="lidar_1_1"/>
</joint>

<joint name="Revolute 2" type="continuous">
  <origin xyz="0.2205 0.096843 0.000881" rpy="0 0 0"/>
  <parent link="base_link"/>
  <child link="left_wheel_1_1"/>
  <axis xyz="1.0 0.0 0.0"/>
</joint>

<joint name="Revolute 3" type="continuous">
  <origin xyz="-0.2205 0.096843 0.000881" rpy="0 0 0"/>
  <parent link="base_link"/>
  <child link="right_wheel_1_1"/>
  <axis xyz="-1.0 0.0 0.0"/>
</joint>

</robot>
